
raise ValueError("throwing an exception")
