
raise ValueError("throwing an exception")

# py.test plugin does not report a test result for this!
